<?xml version="1.0" ?>
<!-- =================================================================================== -->
<!-- |    This document was autogenerated by xacro from /home/nivmini/nivanmodels/derrenyay.urdf.xacro | -->
<!-- |    EDITING THIS FILE BY HAND IS NOT RECOMMENDED                                 | -->
<!-- =================================================================================== -->
<robot name="two_wheeled_robot">
  <!-- ======================================================================================================= -->
  <!-- Properties / Constants -->
  <!-- ======================================================================================================= -->
  <!-- Mass of the base in kg -->
  <!-- Mass of each wheel in kg -->
  <!-- Touch ground -->
  <!-- Place at front -->
  <!-- ======================================================================================================= -->
  <!-- Materials for Gazebo visualization -->
  <!-- ======================================================================================================= -->
  <material name="blue">
    <color rgba="0 0 0.8 1"/>
  </material>
  <material name="black">
    <color rgba="0 0 0 1"/>
  </material>
  <material name="green">
    <color rgba="0 0.8 0 1"/>
  </material>
  <!-- ======================================================================================================= -->
  <!-- Inertia Macros (for calculating moments of inertia) -->
  <!-- ======================================================================================================= -->
  <!-- ======================================================================================================= -->
  <!-- Base Link -->
  <!-- ======================================================================================================= -->
  <link name="base_link">
    <visual>
      <origin rpy="0 0 0" xyz="0 0 0"/>
      <geometry>
        <box size="0.3 0.2 0.1"/>
      </geometry>
      <material name="blue"/>
    </visual>
    <collision>
      <origin rpy="0 0 0" xyz="0 0 0"/>
      <geometry>
        <box size="0.3 0.2 0.1"/>
      </geometry>
    </collision>
    <inertial>
      <origin rpy="0 0 0" xyz="0 0 0"/>
      <mass value="4.0"/>
      <inertia ixx="0.01666666666666667" ixy="0" ixz="0" iyy="0.03333333333333333" iyz="0" izz="0.043333333333333335"/>
    </inertial>
  </link>
  <!-- ======================================================================================================= -->
  <!-- Wheel Macros -->
  <!-- ======================================================================================================= -->
  <link name="left_wheel_link">
    <visual>
      <origin rpy="1.5707963267948966 0 0" xyz="0 0 0"/>
      <!-- Rotate cylinder to align with Y-axis for wheel -->
      <geometry>
        <cylinder length="0.02" radius="0.054"/>
      </geometry>
      <material name="black"/>
    </visual>
    <collision>
      <origin rpy="1.5707963267948966 0 0" xyz="0 0 0"/>
      <geometry>
        <cylinder length="0.02" radius="0.054"/>
      </geometry>
    </collision>
    <inertial>
      <origin rpy="1.5707963267948966 0 0" xyz="0 0 0"/>
      <mass value="0.7"/>
      <inertia ixx="0.0005336333333333333" ixy="0" ixz="0" iyy="0.0005336333333333333" iyz="0" izz="0.0010206"/>
    </inertial>
  </link>
  <joint name="left_wheel_joint" type="continuous">
    <origin rpy="0 0 0" xyz="-0.06 0.11 -0.05"/>
    <parent link="base_link"/>
    <child link="left_wheel_link"/>
    <axis xyz="0 1 0"/>
    <!-- Axis of rotation for wheels (Y-axis) -->
  </joint>
  <!-- Gazebo plugin for wheel joint (for simulation) -->
  <gazebo reference="left_wheel_link">
    <material>Gazebo/Black</material>
    <mu1>1.4</mu1>
    <!-- Friction in primary direction -->
    <mu2>1.4</mu2>
    <!-- Friction in secondary direction -->
  </gazebo>
  <link name="right_wheel_link">
    <visual>
      <origin rpy="1.5707963267948966 0 0" xyz="0 0 0"/>
      <!-- Rotate cylinder to align with Y-axis for wheel -->
      <geometry>
        <cylinder length="0.02" radius="0.054"/>
      </geometry>
      <material name="black"/>
    </visual>
    <collision>
      <origin rpy="1.5707963267948966 0 0" xyz="0 0 0"/>
      <geometry>
        <cylinder length="0.02" radius="0.054"/>
      </geometry>
    </collision>
    <inertial>
      <origin rpy="1.5707963267948966 0 0" xyz="0 0 0"/>
      <mass value="0.7"/>
      <inertia ixx="0.0005336333333333333" ixy="0" ixz="0" iyy="0.0005336333333333333" iyz="0" izz="0.0010206"/>
    </inertial>
  </link>
  <joint name="right_wheel_joint" type="continuous">
    <origin rpy="0 0 0" xyz="-0.06 -0.11 -0.05"/>
    <parent link="base_link"/>
    <child link="right_wheel_link"/>
    <axis xyz="0 1 0"/>
    <!-- Axis of rotation for wheels (Y-axis) -->
  </joint>
  <!-- Gazebo plugin for wheel joint (for simulation) -->
  <gazebo reference="right_wheel_link">
    <material>Gazebo/Black</material>
    <mu1>1.4</mu1>
    <!-- Friction in primary direction -->
    <mu2>1.4</mu2>
    <!-- Friction in secondary direction -->
  </gazebo>
  <!-- ======================================================================================================= -->
  <!-- Caster Ball Link -->
  <!-- ======================================================================================================= -->
  <link name="caster_link">
    <visual>
      <origin rpy="0 0 0" xyz="0 0 0"/>
      <geometry>
        <sphere radius="0.027"/>
      </geometry>
      <material name="black"/>
    </visual>
    <collision>
      <origin rpy="0 0 0" xyz="0 0 0"/>
      <geometry>
        <sphere radius="0.027"/>
      </geometry>
    </collision>
    <inertial>
      <origin rpy="0 0 0" xyz="0 0 0"/>
      <mass value="1"/>
      <inertia ixx="0.0001" ixy="0" ixz="0" iyy="0.0001" iyz="0" izz="0.0001"/>
    </inertial>
  </link>
  <!-- Fixed Joint to attach caster -->
  <joint name="caster_joint" type="fixed">
    <origin rpy="0 0 0" xyz="0.123 0 -0.077"/>
    <parent link="base_link"/>
    <child link="caster_link"/>
  </joint>
  <gazebo reference="caster_link">
    <material>Gazebo/Black</material>
    <mu1>0.6</mu1>
    <!-- Friction in primary direction -->
    <mu2>0.6</mu2>
    <!-- Friction in secondary direction -->
  </gazebo>
  <!-- ======================================================================================================= -->
  <!-- Lidar Link -->
  <!-- ======================================================================================================= -->
  <joint name="laser_joint" type="fixed">
    <parent link="base_link"/>
    <child link="laser_frame"/>
    <origin rpy="0 0 0" xyz="0 0 0.06"/>
  </joint>
  <link name="laser_frame">
    <visual>
      <origin rpy="0 0 0" xyz="0 0 0"/>
      <geometry>
        <cylinder length="0.02" radius="0.05"/>
      </geometry>
      <material name="red">
        <color rgba="1 0 0 1"/>
      </material>
    </visual>
    <collision>
      <origin rpy="0 0 0" xyz="0 0 0"/>
      <geometry>
        <cylinder length="0.02" radius="0.05"/>
      </geometry>
    </collision>
    <inertial>
      <origin rpy="0 0 0" xyz="0 0 0"/>
      <mass value="0.5"/>
      <inertia ixx="0.0003125" ixy="0.0" ixz="0.0" iyy="0.0003125" iyz="0.0" izz="0.000625"/>
    </inertial>
  </link>
  <gazebo reference="laser_frame">
    <material>Gazebo/Red</material>
    <sensor name="laser" type="ray">
      <pose> 0 0 0 0 0 0 </pose>
      <visualize>true</visualize>
      <update_rate>10</update_rate>
      <ray>
        <scan>
          <horizontal>
            <samples>360</samples>
            <min_angle>-3.14</min_angle>
            <max_angle>3.14</max_angle>
          </horizontal>
        </scan>
        <range>
          <min>0.3</min>
          <max>5</max>
        </range>
      </ray>
      <plugin filename="libgazebo_ros_ray_sensor.so" name="laser_controller">
        <ros>
          <argument>~/out:=scan</argument>
        </ros>
        <output_type>sensor_msgs/LaserScan</output_type>
        <topicName>/scan</topicName>
        <frame_name>laser_frame</frame_name>
      </plugin>
    </sensor>
  </gazebo>
  <!-- ======================================================================================================= -->
  <!-- Base_footprint (optional) -->
  <!-- ======================================================================================================= -->
  <link name="base_footprint">
  </link>
  <joint name="base_footprint_joint" type="fixed">
    <origin rpy="0 0 0" xyz="0 0 0"/>
    <parent link="base_footprint"/>
    <child link="base_link"/>
  </joint>
  <!-- ======================================================================================================= -->
  <!-- Gazebo Control Plugins -->
  <!-- ======================================================================================================= -->
  
  
  
  <!-- Gazebo-Classic ros2_control plugin -->
  <gazebo>
    <plugin name="gazebo_ros2_control" filename="libgazebo_ros2_control.so">
      <!-- use your real absolute path below -->
      <parameters>/home/nithin/two_ws/src/two_wheel_bot/config/diff_driv.yaml</parameters>
      <robot_param>robot_description</robot_param>
      <robot_param_node>robot_state_publisher</robot_param_node>
      <controller_manager_name>controller_manager</controller_manager_name>
    </plugin>
  </gazebo>

  <ros2_control name="RobotSystem" type="system">
    <hardware>
      <plugin>gazebo_ros2_control/GazeboSystem</plugin>
    </hardware>
    <joint name="right_wheel_joint">            <!-- match the URDF joint name -->
      <command_interface name="velocity"/>
      <state_interface   name="position"/>
      <state_interface   name="velocity"/>
    </joint>
    <joint name="left_wheel_joint">            <!-- match the URDF joint name -->
      <command_interface name="velocity"/>
      <state_interface   name="position"/>
      <state_interface   name="velocity"/>
    </joint>
  </ros2_control>
      
</robot>

